# Bug Fixes Applied

## Issue 1: ImportError - ConnectionError from telethon.errors

**Error:**
```
ImportError: cannot import name 'ConnectionError' from 'telethon.errors'
```

**Root Cause:**
`ConnectionError` is a built-in Python exception, not a telethon-specific error. The code was trying to import it from `telethon.errors` which doesn't have this exception.

**Files Fixed:**
1. `utils/telegram_helpers.py` - Line 10
2. `utils/improved_upload.py` - Line 9

**Solution:**
- Removed `ConnectionError` and `NetworkError` from telethon imports
- Added comment explaining these are built-in Python exceptions
- Updated exception handling to use the built-in exceptions directly

**Before:**
```python
from telethon.errors import FloodWaitError, MessageNotModifiedError, TimeoutError, ConnectionError
```

**After:**
```python
from telethon.errors import FloodWaitError, MessageNotModifiedError, TimeoutError
# Note: ConnectionError and NetworkError are built-in Python exceptions, not from telethon
```

## Issue 2: Cookie File Directory Not Found

**Error:**
```
Error: Error saving cookies: [Errno 2] No such file or directory: '/tmp/downloads/temp/user_cookies/cookies_884479561.txt'
```

**Root Cause:**
The user cookies directory (`/tmp/downloads/temp/user_cookies/`) was not being created before attempting to save cookie files.

**Files Fixed:**
1. `utils/user_cookies.py` - `save_user_cookies()` method
2. `utils/user_cookies.py` - `cleanup_old_cookies()` method

**Solution:**
- Added `os.makedirs(self.cookies_dir, exist_ok=True)` before saving cookies
- Added directory existence check in cleanup method
- Enhanced error handling for directory operations

**Before:**
```python
def save_user_cookies(self, user_id: int, cookie_content: str) -> Tuple[bool, str]:
    try:
        cookie_path = self.get_user_cookie_path(user_id)
        # ... rest of method
```

**After:**
```python
def save_user_cookies(self, user_id: int, cookie_content: str) -> Tuple[bool, str]:
    try:
        # Ensure the cookies directory exists
        os.makedirs(self.cookies_dir, exist_ok=True)
        
        cookie_path = self.get_user_cookie_path(user_id)
        # ... rest of method
```

## Additional Improvements

### Enhanced Error Handling
- Added proper directory existence checks
- Improved error messages for debugging
- Added defensive programming patterns

### Code Safety
- Fixed undefined `NetworkError` reference in exception handling
- Added proper comments explaining built-in vs telethon exceptions
- Enhanced directory creation with proper error handling

## Testing Verification

To verify these fixes work:

1. **For telethon import fix:**
   - The bot should start without ImportError
   - All upload functionality should work normally

2. **For cookie directory fix:**
   - Users should be able to upload cookie files without getting "No such file or directory" errors
   - Cookie files should be saved to `/tmp/downloads/temp/user_cookies/cookies_{user_id}.txt`

## Files Modified Summary

1. **utils/telegram_helpers.py** - Fixed telethon import error
2. **utils/improved_upload.py** - Fixed telethon import error and NetworkError reference
3. **utils/user_cookies.py** - Fixed directory creation and cleanup issues

These fixes ensure the bot can start properly and handle cookie file uploads without crashing.
